<?xml version="1.0"?>
<robot name="face_screen_support_arm">
  <link name="base_link">
    <visual><geometry><mesh filename="../meshes/base_link.stl" scale="0.001 0.001 0.001"/></geometry></visual>
    <collision><geometry><mesh filename="../meshes/base_link.stl" scale="0.001 0.001 0.001"/></geometry></collision>
    <inertial><origin xyz="0 0 0.05"/><mass value="2.0"/><inertia ixx="0.02" ixy="0" ixz="0" iyy="0.02" iyz="0" izz="0.02"/></inertial>
  </link>

  <joint name="joint1_base_yaw" type="revolute">
    <origin xyz="0 0 0.16" rpy="0 0 0"/>
    <parent link="base_link"/><child link="yaw_link"/>
    <axis xyz="0 0 1"/>
    <limit lower="-2.61799" upper="2.61799" effort="30" velocity="1.5"/>
  </joint>
  <link name="yaw_link">
    <visual><geometry><mesh filename="../meshes/yaw_link.stl" scale="0.001 0.001 0.001"/></geometry></visual>
    <collision><geometry><mesh filename="../meshes/yaw_link.stl" scale="0.001 0.001 0.001"/></geometry></collision>
    <inertial><origin xyz="0 0 0"/><mass value="0.7"/><inertia ixx="0.005" ixy="0" ixz="0" iyy="0.005" iyz="0" izz="0.005"/></inertial>
  </link>

  <joint name="joint2_shoulder_pitch" type="revolute">
    <origin xyz="0 0 0" rpy="0 0 0"/>
    <parent link="yaw_link"/><child link="upper_arm"/>
    <axis xyz="0 1 0"/>
    <limit lower="-3.14159" upper="0" effort="35" velocity="1.2"/>
  </joint>
  <link name="upper_arm">
    <visual><geometry><mesh filename="../meshes/upper_arm.stl" scale="0.001 0.001 0.001"/></geometry></visual>
    <collision><geometry><mesh filename="../meshes/upper_arm.stl" scale="0.001 0.001 0.001"/></geometry></collision>
    <inertial><origin xyz="0.14 0 0"/><mass value="0.8"/><inertia ixx="0.006" ixy="0" ixz="0" iyy="0.02" iyz="0" izz="0.02"/></inertial>
  </link>

  <joint name="joint3_elbow_pitch" type="revolute">
    <origin xyz="0.28 0 0" rpy="0 0 0"/>
    <parent link="upper_arm"/><child link="forearm"/>
    <axis xyz="0 1 0"/>
    <limit lower="-2.0944" upper="2.61799" effort="30" velocity="1.2"/>
  </joint>
  <link name="forearm">
    <visual><geometry><mesh filename="../meshes/forearm.stl" scale="0.001 0.001 0.001"/></geometry></visual>
    <collision><geometry><mesh filename="../meshes/forearm.stl" scale="0.001 0.001 0.001"/></geometry></collision>
    <inertial><origin xyz="0.12 0 0"/><mass value="0.7"/><inertia ixx="0.004" ixy="0" ixz="0" iyy="0.015" iyz="0" izz="0.015"/></inertial>
  </link>

  <joint name="joint4_telescopic" type="prismatic">
    <origin xyz="0.24 0 0" rpy="0 0 0"/>
    <parent link="forearm"/><child link="telescopic_slider"/>
    <axis xyz="1 0 0"/>
    <limit lower="0" upper="0.45" effort="120" velocity="0.25"/>
  </joint>
  <link name="telescopic_slider">
    <visual><geometry><mesh filename="../meshes/telescopic_slider.stl" scale="0.001 0.001 0.001"/></geometry></visual>
    <collision><geometry><mesh filename="../meshes/telescopic_slider.stl" scale="0.001 0.001 0.001"/></geometry></collision>
    <inertial><origin xyz="0 0 0.04"/><mass value="0.55"/><inertia ixx="0.003" ixy="0" ixz="0" iyy="0.012" iyz="0" izz="0.012"/></inertial>
  </link>

  <joint name="joint5_screen_pan" type="revolute">
    <origin xyz="0.085 0 0.024" rpy="0 0 0"/>
    <parent link="telescopic_slider"/><child link="screen_pan_link"/>
    <axis xyz="0 0 1"/>
    <limit lower="-3.14159" upper="3.14159" effort="8" velocity="2.0"/>
  </joint>
  <link name="screen_pan_link">
    <visual><geometry><mesh filename="../meshes/screen_pan_link.stl" scale="0.001 0.001 0.001"/></geometry></visual>
    <collision><geometry><mesh filename="../meshes/screen_pan_link.stl" scale="0.001 0.001 0.001"/></geometry></collision>
    <inertial><origin xyz="0 0 0"/><mass value="0.25"/><inertia ixx="0.001" ixy="0" ixz="0" iyy="0.001" iyz="0" izz="0.001"/></inertial>
  </link>

  <joint name="joint6_screen_pitch" type="revolute">
    <origin xyz="0.05 0 0.042" rpy="0 0 0"/>
    <parent link="screen_pan_link"/><child link="screen_pitch_link"/>
    <axis xyz="0 1 0"/>
    <limit lower="-1.0472" upper="1.0472" effort="8" velocity="2.0"/>
  </joint>
  <link name="screen_pitch_link">
    <visual><geometry><mesh filename="../meshes/screen_pitch_link.stl" scale="0.001 0.001 0.001"/></geometry></visual>
    <inertial><origin xyz="0.04 0 0"/><mass value="0.65"/><inertia ixx="0.006" ixy="0" ixz="0" iyy="0.004" iyz="0" izz="0.008"/></inertial>
  </link>

  <joint name="screen_center_fixed" type="fixed">
    <origin xyz="0.052 0 0.072" rpy="0 0 0"/>
    <parent link="screen_pitch_link"/><child link="screen_center"/>
  </joint>
  <link name="screen_center"/>
</robot>
