<?xml version='1.0' encoding='utf-8'?>
<robot name="face_screen_support_arm_depth_camera">
  <material name="depth_camera_lens">
    <color rgba="0 0 0 1" />
  </material>
  <material name="depth_camera_body">
    <color rgba="0.30 0.31 0.33 1" />
  </material>
  <material name="neutral_gray">
    <color rgba="0.78 0.78 0.76 1" />
  </material>
  <material name="joint_sky_blue">
    <color rgba="0.529 0.808 0.922 1" />
  </material>
  <material name="screen_black">
    <color rgba="0 0 0 1" />
  </material>
  <material name="center_red">
    <color rgba="1 0 0 1" />
  </material>
  <material name="office_desk_wood">
    <color rgba="0.62 0.42 0.24 1" />
  </material>
  <link name="desk_link">
    <visual name="office_desk">
      <geometry>
        <mesh filename="../meshes/office_desk.stl" scale="0.001 0.001 0.001" />
      </geometry>
      <material name="office_desk_wood" />
    </visual>
    <collision>
      <geometry>
        <mesh filename="../meshes/office_desk.stl" scale="0.001 0.001 0.001" />
      </geometry>
    </collision>
    <inertial>
      <origin xyz="0 0 0.37" rpy="0 0 0" />
      <mass value="25.0" />
      <inertia ixx="4.3" ixy="0" ixz="0" iyy="1.4" iyz="0" izz="5.4" />
    </inertial>
  </link>
  <joint name="desk_to_arm_base" type="fixed">
    <origin xyz="-0.150 0.000 0.740" rpy="0 0 0" />
    <parent link="desk_link" />
    <child link="base_link" />
  </joint>
  <link name="base_link">
    <visual name="base_disc">
      <geometry>
        <mesh filename="../visuals/base_disc.stl" scale="0.001 0.001 0.001" />
      </geometry>
      <material name="neutral_gray" />
    </visual>
    <visual name="mast">
      <geometry>
        <mesh filename="../visuals/mast.stl" scale="0.001 0.001 0.001" />
      </geometry>
      <material name="neutral_gray" />
    </visual>
    <visual name="depth_camera_body">
      <origin xyz="0.038 0.000 0.060" rpy="1.570796 0 1.570796" />
      <geometry>
        <mesh filename="../visuals/depth_camera_body.stl" scale="0.001 0.001 0.001" />
      </geometry>
      <material name="depth_camera_body" />
    </visual>
    <visual name="depth_camera_lens">
      <origin xyz="0.038 0.000 0.060" rpy="1.570796 0 1.570796" />
      <geometry>
        <mesh filename="../visuals/depth_camera_lens.stl" scale="0.001 0.001 0.001" />
      </geometry>
      <material name="depth_camera_lens" />
    </visual>
    <collision>
      <geometry>
        <mesh filename="../meshes/base_link.stl" scale="0.001 0.001 0.001" />
      </geometry>
    </collision>
    <inertial>
      <origin xyz="0 0 0.05" />
      <mass value="2.0" />
      <inertia ixx="0.02" ixy="0" ixz="0" iyy="0.02" iyz="0" izz="0.02" />
    </inertial>
  </link>
  <joint name="joint1_base_yaw" type="revolute">
    <origin xyz="0 0 0.16" rpy="0 0 0" />
    <parent link="base_link" />
    <child link="yaw_link" />
    <axis xyz="0 0 1" />
    <limit lower="-2.61799" upper="2.61799" effort="30" velocity="1.5" />
  </joint>
  <link name="yaw_link">
    <visual name="yaw_bearing">
      <geometry>
        <mesh filename="../visuals/yaw_bearing.stl" scale="0.001 0.001 0.001" />
      </geometry>
      <material name="joint_sky_blue" />
    </visual>
    <visual name="shoulder_yoke_l">
      <geometry>
        <mesh filename="../visuals/shoulder_yoke_l.stl" scale="0.001 0.001 0.001" />
      </geometry>
      <material name="joint_sky_blue" />
    </visual>
    <visual name="shoulder_yoke_r">
      <geometry>
        <mesh filename="../visuals/shoulder_yoke_r.stl" scale="0.001 0.001 0.001" />
      </geometry>
      <material name="joint_sky_blue" />
    </visual>
    <visual name="joint2_axis_hint">
      <geometry>
        <mesh filename="../visuals/joint2_axis_hint.stl" scale="0.001 0.001 0.001" />
      </geometry>
      <material name="joint_sky_blue" />
    </visual>
    <collision>
      <geometry>
        <mesh filename="../meshes/yaw_link.stl" scale="0.001 0.001 0.001" />
      </geometry>
    </collision>
    <inertial>
      <origin xyz="0 0 0" />
      <mass value="0.7" />
      <inertia ixx="0.005" ixy="0" ixz="0" iyy="0.005" iyz="0" izz="0.005" />
    </inertial>
  </link>
  <joint name="joint2_shoulder_pitch" type="revolute">
    <origin xyz="0 0 0" rpy="0 0 0" />
    <parent link="yaw_link" />
    <child link="upper_arm" />
    <axis xyz="0 1 0" />
    <limit lower="-3.49066" upper="0.349066" effort="35" velocity="1.2" />
  </joint>
  <link name="upper_arm">
    <visual name="upper_bar">
      <geometry>
        <mesh filename="../visuals/upper_bar.stl" scale="0.001 0.001 0.001" />
      </geometry>
      <material name="neutral_gray" />
    </visual>
    <visual name="upper_shoulder_hub">
      <geometry>
        <mesh filename="../visuals/upper_shoulder_hub.stl" scale="0.001 0.001 0.001" />
      </geometry>
      <material name="joint_sky_blue" />
    </visual>
    <visual name="upper_elbow_hub">
      <geometry>
        <mesh filename="../visuals/upper_elbow_hub.stl" scale="0.001 0.001 0.001" />
      </geometry>
      <material name="joint_sky_blue" />
    </visual>
    <collision>
      <geometry>
        <mesh filename="../meshes/upper_arm.stl" scale="0.001 0.001 0.001" />
      </geometry>
    </collision>
    <inertial>
      <origin xyz="0.14 0 0" />
      <mass value="0.8" />
      <inertia ixx="0.006" ixy="0" ixz="0" iyy="0.02" iyz="0" izz="0.02" />
    </inertial>
  </link>
  <joint name="joint3_elbow_pitch" type="revolute">
    <origin xyz="0.28 0 0" rpy="0 0 0" />
    <parent link="upper_arm" />
    <child link="forearm" />
    <axis xyz="0 1 0" />
    <limit lower="-2.96706" upper="2.96706" effort="30" velocity="1.2" />
  </joint>
  <link name="forearm">
    <visual name="forearm_bar">
      <geometry>
        <mesh filename="../visuals/forearm_bar.stl" scale="0.001 0.001 0.001" />
      </geometry>
      <material name="neutral_gray" />
    </visual>
    <visual name="forearm_elbow_hub">
      <geometry>
        <mesh filename="../visuals/forearm_elbow_hub.stl" scale="0.001 0.001 0.001" />
      </geometry>
      <material name="joint_sky_blue" />
    </visual>
    <visual name="slider_outer_tube">
      <geometry>
        <mesh filename="../visuals/slider_outer_tube.stl" scale="0.001 0.001 0.001" />
      </geometry>
      <material name="neutral_gray" />
    </visual>
    <collision>
      <geometry>
        <mesh filename="../meshes/forearm.stl" scale="0.001 0.001 0.001" />
      </geometry>
    </collision>
    <inertial>
      <origin xyz="0.12 0 0" />
      <mass value="0.7" />
      <inertia ixx="0.004" ixy="0" ixz="0" iyy="0.015" iyz="0" izz="0.015" />
    </inertial>
  </link>
  <joint name="joint4_telescopic" type="prismatic">
    <origin xyz="0.24 0 0" rpy="0 0 0" />
    <parent link="forearm" />
    <child link="telescopic_slider" />
    <axis xyz="1 0 0" />
    <limit lower="0" upper="0.28" effort="120" velocity="0.25" />
  </joint>
  <link name="telescopic_slider">
    <visual name="inner_tube">
      <geometry>
        <mesh filename="../visuals/inner_tube.stl" scale="0.001 0.001 0.001" />
      </geometry>
      <material name="neutral_gray" />
    </visual>
    <visual name="linear_rail_hint">
      <geometry>
        <mesh filename="../visuals/linear_rail_hint.stl" scale="0.001 0.001 0.001" />
      </geometry>
      <material name="neutral_gray" />
    </visual>
    <visual name="telescopic_end_cap">
      <geometry>
        <mesh filename="../visuals/telescopic_end_cap.stl" scale="0.001 0.001 0.001" />
      </geometry>
      <material name="neutral_gray" />
    </visual>
    <visual name="pan_mount_boss">
      <geometry>
        <mesh filename="../visuals/pan_mount_boss.stl" scale="0.001 0.001 0.001" />
      </geometry>
      <material name="joint_sky_blue" />
    </visual>
    <collision>
      <geometry>
        <mesh filename="../meshes/telescopic_slider.stl" scale="0.001 0.001 0.001" />
      </geometry>
    </collision>
    <inertial>
      <origin xyz="0 0 0.04" />
      <mass value="0.55" />
      <inertia ixx="0.003" ixy="0" ixz="0" iyy="0.012" iyz="0" izz="0.012" />
    </inertial>
  </link>
  <joint name="joint5_screen_pan" type="revolute">
    <origin xyz="0.085 0 0.024" rpy="0 0 0" />
    <parent link="telescopic_slider" />
    <child link="screen_pan_link" />
    <axis xyz="0 0 1" />
      <limit lower="-1.74533" upper="1.74533" effort="8" velocity="2.0" />
  </joint>
  <link name="screen_pan_link">
    <visual name="pan_base_disc">
      <geometry>
        <mesh filename="../visuals/pan_base_disc.stl" scale="0.001 0.001 0.001" />
      </geometry>
      <material name="joint_sky_blue" />
    </visual>
    <visual name="pan_rotor_cap">
      <geometry>
        <mesh filename="../visuals/pan_rotor_cap.stl" scale="0.001 0.001 0.001" />
      </geometry>
      <material name="joint_sky_blue" />
    </visual>
    <visual name="low_pitch_bridge">
      <geometry>
        <mesh filename="../visuals/low_pitch_bridge.stl" scale="0.001 0.001 0.001" />
      </geometry>
      <material name="neutral_gray" />
    </visual>
    <visual name="pitch_side_plate_l">
      <geometry>
        <mesh filename="../visuals/pitch_side_plate_l.stl" scale="0.001 0.001 0.001" />
      </geometry>
      <material name="joint_sky_blue" />
    </visual>
    <visual name="pitch_side_plate_r">
      <geometry>
        <mesh filename="../visuals/pitch_side_plate_r.stl" scale="0.001 0.001 0.001" />
      </geometry>
      <material name="joint_sky_blue" />
    </visual>
    <visual name="pitch_axis_hint">
      <geometry>
        <mesh filename="../visuals/pitch_axis_hint.stl" scale="0.001 0.001 0.001" />
      </geometry>
      <material name="joint_sky_blue" />
    </visual>
    <collision>
      <geometry>
        <mesh filename="../meshes/screen_pan_link.stl" scale="0.001 0.001 0.001" />
      </geometry>
    </collision>
    <inertial>
      <origin xyz="0 0 0" />
      <mass value="0.25" />
      <inertia ixx="0.001" ixy="0" ixz="0" iyy="0.001" iyz="0" izz="0.001" />
    </inertial>
  </link>
  <joint name="joint6_screen_pitch" type="revolute">
    <origin xyz="0.07 0 0.042" rpy="0 0 0" />
    <parent link="screen_pan_link" />
    <child link="screen_pitch_link" />
    <axis xyz="0 1 0" />
    <limit lower="-1.0472" upper="1.0472" effort="8" velocity="2.0" />
  </joint>
  <link name="screen_pitch_link">
    <visual name="screen_pitch_hub">
      <geometry>
        <mesh filename="../visuals/screen_pitch_hub.stl" scale="0.001 0.001 0.001" />
      </geometry>
      <material name="joint_sky_blue" />
    </visual>
    <visual name="screen_plate">
      <geometry>
        <mesh filename="../visuals/screen_plate.stl" scale="0.001 0.001 0.001" />
      </geometry>
      <material name="screen_black" />
    </visual>
    <visual name="screen_lower_mount">
      <geometry>
        <mesh filename="../visuals/screen_lower_mount.stl" scale="0.001 0.001 0.001" />
      </geometry>
      <material name="neutral_gray" />
    </visual>
    <visual name="screen_back_mount">
      <geometry>
        <mesh filename="../visuals/screen_back_mount.stl" scale="0.001 0.001 0.001" />
      </geometry>
      <material name="neutral_gray" />
    </visual>
    <visual name="screen_center_marker">
      <geometry>
        <mesh filename="../visuals/screen_center_marker.stl" scale="0.001 0.001 0.001" />
      </geometry>
      <material name="center_red" />
    </visual>
    <inertial>
      <origin xyz="0.04 0 0" />
      <mass value="0.65" />
      <inertia ixx="0.006" ixy="0" ixz="0" iyy="0.004" iyz="0" izz="0.008" />
    </inertial>
  </link>
  <joint name="screen_center_fixed" type="fixed">
    <origin xyz="0.052 0 0.0" rpy="0 0 0" />
    <parent link="screen_pitch_link" />
    <child link="screen_center" />
  </joint>
  <link name="screen_center" />
</robot>
